Workbook

Sheet Códigos detectados
A1: Código | B1: NOMBRE ARTICULO
A2: IPT-004180 | B2: =IFERROR(VLOOKUP(A2, NOMBRES!$A$2:$B$3000, 2, 0), "aa") -> TABLA PORTAPAPELES A4 AZUL COMIX
A3: IPT-004181 | B3: =IFERROR(VLOOKUP(A3, NOMBRES!$A$2:$B$3000, 2, 0), "aa") -> TABLA PORTAPAPELES A4 MARRON COMIX
A4: IPT-004188 | B4: =IFERROR(VLOOKUP(A4, NOMBRES!$A$2:$B$3000, 2, 0), "aa") -> MARCADOR DE PIZARRA ROJO COMIX
A5: IPT-004195 | B5: =IFERROR(VLOOKUP(A5, NOMBRES!$A$2:$B$3000, 2, 0), "aa") -> CLIP DE PAPEL 29MM STELL 150U COMIX
A6: IPT-004192 | B6: =IFERROR(VLOOKUP(A6, NOMBRES!$A$2:$B$3000, 2, 0), "aa") -> LAPIZ HB NEGRO 12U COMIX
A7: IPT-000005 | B7: =IFERROR(VLOOKUP(A7, NOMBRES!$A$2:$B$3000, 2, 0), "aa") -> ROLLO DE ETIQUETA ZEBRA 31X25MM 2000U
A8: IPT-004198 | B8: =IFERROR(VLOOKUP(A8, NOMBRES!$A$2:$B$3000, 2, 0), "aa") -> GOMA DE BORRAR BLANCO 6CM COMIX
A9: IPT-004199 | B9: =IFERROR(VLOOKUP(A9, NOMBRES!$A$2:$B$3000, 2, 0), "aa") -> REGLA TRANSPARENT 30CM COMIX
A10: IPT-000004 | B10: =IFERROR(VLOOKUP(A10, NOMBRES!$A$2:$B$3000, 2, 0), "aa") -> ROLLO TERMICO DE PUNTO DE VENTA 57X36MM
A11: MT-MP1512 | B11: =IFERROR(VLOOKUP(A11, NOMBRES!$A$2:$B$3000, 2, 0), "aa") -> SET DE ACUARELAS MOTARRO 12 COLORES
A12: IPT-004194 | B12: =IFERROR(VLOOKUP(A12, NOMBRES!$A$2:$B$3000, 2, 0), "aa") -> PERFORADORA 8CM BLANCO COMIX
A13: IPT-004204 | B13: =IFERROR(VLOOKUP(A13, NOMBRES!$A$2:$B$3000, 2, 0), "aa") -> CALCULADORA BLANCA COMIX
... A134: IPT-000003 | B134: =IFERROR(VLOOKUP(A134, NOMBRES!$A$2:$B$3000, 2, 0), "aa") -> ROLLO DE IMPRESORA FISCAL 80X65MM

Sheet NOMBRES
A1: Código de artículo | B1: Nombre del producto | C1: Nombre de búsqueda | D1: Tipo de producto | E1: Subtipo de producto | F1: Grupo de dimensiones de producto | G1: Tipo de producción
A2: AF-000001 | B2: FREEZER SKIMO 516L | C2: FREEZER SKIMO | D2: Artículo | E2: Producto | G2: L. MAT
A3: AF-000004 | B3: CESTAS NEGRAS FRESERAS | C3: CESTAS | D3: Artículo | E3: Producto | G3: L. MAT
A4: AF-000005 | B4: NEVERA EXHIBIDORA OSTER 226L | C4: NEVERA EXHIBIDORA OS | D4: Artículo | E4: Producto | G4: L. MAT
A5: AF-000006 | B5: CONTADORA DE BILLETES FALSO SILVER S3500 | C5: CONTADORA DE BILLETE | D5: Artículo | E5: Producto | G5: L. MAT
A6: AF-000007 | B6: SELLADORA DE 36CM MESA | C6: SELLADORA DE 36CM | D6: Artículo | E6: Producto | G6: L. MAT
A7: AF-000008 | B7: UPS POWER PLUS 1000VA | C7: UPS | D7: Artículo | E7: Producto | G7: L. MAT
A8: AF-000009 | B8: FREEZER SKIMO KX12ZQD | C8: FREEZER SKIMO | D8: Artículo | E8: Producto | G8: L. MAT
A9: AF-000010 | B9: NEVERA 2 PUERTAS SKIMO KX12HFC | C9: NEVERA 2 PUERTAS | D9: Artículo | E9: Producto | G9: L. MAT
A10: AF-000011 | B10: LED LIGHT FREEZER SKIMO | C10: LED LIGHT FREEZER | D10: Artículo | E10: Producto | G10: L. MAT
A11: AF-000012 | B11: FAN MOTOR FREEZER SKIMO | C11: FAN MOTOR SKIMO | D11: Artículo | E11: Producto | G11: L. MAT
A12: AF-000013 | B12: DIGITAL CONTROLLER SKIMO | C12: DIGITAL CONTROLLER S | D12: Artículo | E12: Producto | G12: L. MAT
A13: AF-000014 | B13: MAQUINA DE ALGODON DE AZUCAR | C13: MAQUINA DE ALGODON | D13: Artículo | E13: Producto | G13: L. MAT
... A68: AK-000261 | B68: VIANDA | C68: VIANDA | D68: Artículo | E68: Producto | G68: L. MAT
A69: AK-000273 | B69: CUBO DE ALMACENAMIENTO 90LT UNICOLOR | C69: CUBO DE ALMACENAMIEN | D69: Artículo | E69: Producto maestro | F69: C | G69: L. MAT
A70: AK-000276 | B70: CUBO DE ALMACENAMIENTO 90LT TRANSPARENTE | C70: CUBO DE ALMACENAMIEN | D70: Artículo | E70: Producto | G70: L. MAT
A71: AK-000302 | B71: CESTA DE ROPA | C71: CESTA DE ROPA | D71: Artículo | E71: Producto | G71: L. MAT
A72: AK-000308 | B72: BANCO PEQUEÑO UNICOLOR | C72: BANCO PEQUEÑO | D72: Artículo | E72: Producto maestro | F72: C | G72: L. MAT
A73: AK-000309 | B73: BANCO GRANDE UNICOLOR | C73: BANCO GRANDE | D73: Artículo | E73: Producto maestro | F73: C | G73: L. MAT
A74: AK-000326 | B74: TABLA DE CORTAR | C74: TABLA DE CORTAR | D74: Artículo | E74: Producto | G74: L. MAT
A75: AK-000332 | B75: JARRA DE CRISTAL | C75: JARRA DE CRISTAL | D75: Artículo | E75: Producto | G75: L. MAT
A76: AK-000348 | B76: CAJA DE CUBERTERIA | C76: CAJA DE CUBERTERIA | D76: Artículo | E76: Producto | G76: L. MAT
A77: AK-000349 | B77: CAJA DE CUBERTERIA | C77: CAJA DE CUBERTERIA | D77: Artículo | E77: Producto | G77: L. MAT
A78: AK-000351 | B78: CAJON DE PAN | C78: CAJON DE PAN | D78: Artículo | E78: Producto | G78: L. MAT
A79: AK-000358 | B79: COLADOR | C79: COLADOR | D79: Artículo | E79: Producto | G79: L. MAT
A80: AK-000384 | B80: VIANDA | C80: VIANDA | D80: Artículo | E80: Producto | G80: L. MAT
A81: AK-000394 | B81: VIANDA | C81: VIANDA | D81: Artículo | E81: Producto maestro | F81: C | G81: L. MAT
A82: AK-000405 | B82: ENVASE | C82: ENVASE | D82: Artículo | E82: Producto | G82: L. MAT
A83: AK-000429 | B83: ENVASE CON TAPA 22LT TRANSPARENTE | C83: ENVASE CON TAPA 22LT | D83: Artículo | E83: Producto | G83: L. MAT
A84: AK-000434 | B84: GANCHOS 4U | C84: GANCHOS 4U | D84: Artículo | E84: Producto | G84: L. MAT
A85: AK-000458 | B85: CESTA DE PICNIC | C85: CESTA DE PICNIC | D85: Artículo | E85: Producto | G85: L. MAT
A86: AK-000480 | B86: CESTA DE ROPA CUADRADA 41LT | C86: CESTA DE ROPA 41LT | D86: Artículo | E86: Producto maestro | F86: C | G86: L. MAT
A87: AK-000483 | B87: CAJA DE ALMACENAMIENTO 6LT | C87: CAJA DE ALMACENAMIEN | D87: Artículo | E87: Producto | G87: L. MAT
A88: AK-000494 | B88: CAJA DE ALMACENAMIENTO 50LT | C88: CAJA DE ALMACENAMIEN | D88: Artículo | E88: Producto | G88: L. MAT
A89: AK-000495 | B89: CONTENEDOR PARA ALMACENAMIENTO 50LT | C89: CONTENEDOR PARA ALMA | D89: Artículo | E89: Producto maestro | F89: C | G89: L. MAT
A90: AK-000500 | B90: ORGANIZADOR | C90: ORGANIZADOR | D90: Artículo | E90: Producto | G90: L. MAT
A91: AK-000508 | B91: BANCO GIRATORIO | C91: BANCO GIRATORIO | D91: Artículo | E91: Producto maestro | F91: C | G91: L. MAT
A92: AK-000514 | B92: ORGANIZADOR COLGANTE | C92: ORGANIZADOR COLGANTE | D92: Artículo | E92: Producto | G92: L. MAT
A93: AK-000516 | B93: ZAPATERIA | C93: ZAPATERIA | D93: Artículo | E93: Producto | G93: L. MAT
A94: AK-000537 | B94: TAZA CON TAPA | C94: TAZA CON TAPA | D94: Artículo | E94: Producto | G94: L. MAT
...
